[2023-10-05T14:01:07.197+0000] {taskinstance.py:1157} INFO - Dependencies all met for dep_context=non-requeueable deps ti=<TaskInstance: load_to_bigquery_dag.load_to_bigquery manual__2023-10-05T14:01:04.182972+00:00 [queued]>
[2023-10-05T14:01:07.204+0000] {taskinstance.py:1157} INFO - Dependencies all met for dep_context=requeueable deps ti=<TaskInstance: load_to_bigquery_dag.load_to_bigquery manual__2023-10-05T14:01:04.182972+00:00 [queued]>
[2023-10-05T14:01:07.205+0000] {taskinstance.py:1359} INFO - Starting attempt 1 of 1
[2023-10-05T14:01:07.215+0000] {taskinstance.py:1380} INFO - Executing <Task(PythonOperator): load_to_bigquery> on 2023-10-05 14:01:04.182972+00:00
[2023-10-05T14:01:07.225+0000] {standard_task_runner.py:57} INFO - Started process 3217 to run task
[2023-10-05T14:01:07.230+0000] {standard_task_runner.py:84} INFO - Running: ['***', 'tasks', 'run', 'load_to_bigquery_dag', 'load_to_bigquery', 'manual__2023-10-05T14:01:04.182972+00:00', '--job-id', '34', '--raw', '--subdir', 'DAGS_FOLDER/load_to_bigquery_dag.py', '--cfg-path', '/tmp/tmpah9fkd7l']
[2023-10-05T14:01:07.236+0000] {standard_task_runner.py:85} INFO - Job 34: Subtask load_to_bigquery
[2023-10-05T14:01:07.323+0000] {task_command.py:415} INFO - Running <TaskInstance: load_to_bigquery_dag.load_to_bigquery manual__2023-10-05T14:01:04.182972+00:00 [running]> on host bd744fef73d7
[2023-10-05T14:01:07.492+0000] {taskinstance.py:1660} INFO - Exporting env vars: AIRFLOW_CTX_DAG_OWNER='admin' AIRFLOW_CTX_DAG_ID='load_to_bigquery_dag' AIRFLOW_CTX_TASK_ID='load_to_bigquery' AIRFLOW_CTX_EXECUTION_DATE='2023-10-05T14:01:04.182972+00:00' AIRFLOW_CTX_TRY_NUMBER='1' AIRFLOW_CTX_DAG_RUN_ID='manual__2023-10-05T14:01:04.182972+00:00'
[2023-10-05T14:01:07.496+0000] {taskinstance.py:1935} ERROR - Task failed with exception
Traceback (most recent call last):
  File "/home/airflow/.local/lib/python3.8/site-packages/airflow/operators/python.py", line 192, in execute
    return_value = self.execute_callable()
  File "/home/airflow/.local/lib/python3.8/site-packages/airflow/operators/python.py", line 209, in execute_callable
    return self.python_callable(*self.op_args, **self.op_kwargs)
TypeError: load_json_to_bigquery() missing 3 required positional arguments: 'client', 'dataset_id', and 'table_names'
[2023-10-05T14:01:07.510+0000] {taskinstance.py:1398} INFO - Marking task as FAILED. dag_id=load_to_bigquery_dag, task_id=load_to_bigquery, execution_date=20231005T140104, start_date=20231005T140107, end_date=20231005T140107
[2023-10-05T14:01:07.526+0000] {standard_task_runner.py:104} ERROR - Failed to execute job 34 for task load_to_bigquery (load_json_to_bigquery() missing 3 required positional arguments: 'client', 'dataset_id', and 'table_names'; 3217)
[2023-10-05T14:01:07.566+0000] {local_task_job_runner.py:228} INFO - Task exited with return code 1
[2023-10-05T14:01:07.590+0000] {taskinstance.py:2776} INFO - 0 downstream tasks scheduled from follow-on schedule check
